Workbook

Sheet preface
E2: x | F2: y | I2: =_xlfn.CONCAT(I3:I20,J3:J20) -> BeginTeam TeamID=0 Tech=TECH_HUNTING Tech=TECH_AGRICULTURE ContactWithTeam=1 RevealMap=0 EndTeam BeginTeam TeamID=1 Tech=TECH_HUNTING Tech=TECH_AGRICULTURE ContactWithTeam=0 RevealMap=0 EndTeam BeginTeam TeamID=2 Tech=TECH_FISHING Tech=TECH_HUNTING EspionageTeam=5, EspionageAmount=5 EspionageEverAmount=9 RevealMap=0 EndTeam BeginTeam TeamID=3 Tech=TECH_MYSTICISM Tech=TECH_MINING EspionageTeam=10, EspionageAmount=4 EspionageEverAmount=8 RevealMap=0 EndTeam BeginTeam TeamID=4 Tech=TECH_HUNTING Tech=TECH_MINING RevealMap=0 EndTeam BeginTeam TeamID=5 Tech=TECH_AGRICULTURE Tech=TECH_HUNTING RevealMap=0 EndTeam BeginTeam TeamID=6 Tech=TECH_FISHING Tech=TECH_MINING RevealMap=0 EndTeam BeginTeam TeamID=7 Tech=TECH_HUNTING Tech=TECH_MINING RevealMap=0 EndTeam BeginTeam TeamID=8 Tech=TECH_THE_WHEEL Tech=TECH_HUNTING RevealMap=0 EndTeam BeginTeam TeamID=9 Tech=TECH_THE_WHEEL Tech=TECH_AGRICULTURE EspionageEverAmount=4 RevealMap=0 EndTeam BeginTeam TeamID=10 Tech=TECH_MYSTICISM Tech=TECH_AGRICULTURE RevealMap=0 EndTeam BeginTeam TeamID=11 Tech=TECH_MYSTICISM Tech=TECH_FISHING RevealMap=0 EndTeam BeginTeam TeamID=12 Tech=TECH_THE_WHEEL Tech=TECH_AGRICULTURE RevealMap=0 EndTeam BeginTeam TeamID=13 Tech=TECH_THE_WHEEL Tech=TECH_MINING RevealMap=0 EndTeam BeginTeam TeamID=14 Tech=TECH_MYSTICISM Tech=TECH_HUNTING RevealMap=0 EndTeam BeginTeam TeamID=15 Tech=TECH_AGRICULTURE Tech=TECH_MINING EspionageTeam=5, EspionageAmount=5 EspionageEverAmount=9 RevealMap=0 EndTeam BeginTeam TeamID=16 Tech=TECH_MYSTICISM Tech=TECH_THE_WHEEL RevealMap=0 EndTeam BeginTeam TeamID=17 Tech=TECH_FISHING Tech=TECH_THE_WHEEL RevealMap=0 EndTeam BeginPlayer Team=0 LeaderType=LEADER_FRANKLIN_ROOSEVELT LeaderName=Jack CivDesc=American Empire CivShortDesc=TXT_KEY_CIV_AMERICA_SHORT_DESC CivAdjective=TXT_KEY_CIV_AMERICA_ADJECTIVE FlagDecal=Art/Interface/TeamColor/FlagDECAL_Star.dds WhiteFlag=0 CivType=CIVILIZATION_AMERICA Color=PLAYERCOLOR_BLUE ArtStyle=ARTSTYLE_EUROPEAN PlayableCiv=1 MinorNationStatus=0 StartingGold=100 StartingX=25,StartingY=37 StateReligion= StartingEra=ERA_ANCIENT RandomStartLocation=false CivicOption=CIVICOPTION_GOVERNMENT, Civic=CIVIC_DESPOTISM CivicOption=CIVICOPTION_LEGAL, Civic=CIVIC_BARBARISM CivicOption=CIVICOPTION_LABOR, Civic=CIVIC_TRIBALISM CivicOption=CIVICOPTION_ECONOMY, Civic=CIVIC_DECENTRALIZATION CivicOption=CIVICOPTION_RELIGION, Civic=CIVIC_PAGANISM Handicap=HANDICAP_NOBLE EndPlayer BeginPlayer Team=1 LeaderType=LEADER_JULIUS_CAESAR LeaderName=Julius Caesar CivDesc=Roman Empire CivShortDesc=TXT_KEY_CIV_ROME_SHORT_DESC CivAdjective=TXT_KEY_CIV_ROME_ADJECTIVE FlagDecal=Art/Interface/TeamColor/FlagDECAL_Laurels.dds WhiteFlag=0 CivType=CIVILIZATION_ROME Color=PLAYERCOLOR_DARK_PURPLE ArtStyle=ARTSTYLE_GRECO_ROMAN PlayableCiv=1 MinorNationStatus=0 StartingGold=100 StartingX=22,StartingY=17 StateReligion= StartingEra=ERA_ANCIENT RandomStartLocation=false CivicOption=CIVICOPTION_GOVERNMENT, Civic=CIVIC_DESPOTISM CivicOption=CIVICOPTION_LEGAL, Civic=CIVIC_BARBARISM CivicOption=CIVICOPTION_LABOR, Civic=CIVIC_TRIBALISM CivicOption=CIVICOPTION_ECONOMY, Civic=CIVIC_DECENTRALIZATION CivicOption=CIVICOPTION_RELIGION, Civic=CIVIC_PAGANISM Handicap=HANDICAP_NOBLE EndPlayer BeginPlayer Team=2 LeaderType=LEADER_ALEXANDER LeaderName=Alexander CivDesc=Greek Empire CivShortDesc=TXT_KEY_CIV_GREECE_SHORT_DESC CivAdjective=TXT_KEY_CIV_GREECE_ADJECTIVE FlagDecal=Art/Interface/TeamColor/FlagDECAL_Helmet.dds WhiteFlag=0 CivType=CIVILIZATION_GREECE Color=PLAYERCOLOR_LIGHT_BLUE ArtStyle=ARTSTYLE_GRECO_ROMAN PlayableCiv=1 MinorNationStatus=0 StartingGold=100 StartingX=50,StartingY=27 StateReligion= StartingEra=ERA_ANCIENT RandomStartLocation=false CivicOption=CIVICOPTION_GOVERNMENT, Civic=CIVIC_DESPOTISM CivicOption=CIVICOPTION_LEGAL, Civic=CIVIC_BARBARISM CivicOption=CIVICOPTION_LABOR, Civic=CIVIC_TRIBALISM CivicOption=CIVICOPTION_ECONOMY, Civic=CIVIC_DECENTRALIZATION CivicOption=CIVICOPTION_RELIGION, Civic=CIVIC_PAGANISM Handicap=HANDICAP_NOBLE EndPlayer BeginPlayer Team=3 LeaderType=LEADER_ASOKA LeaderName=Asoka CivDesc=Indian Empire CivShortDesc=TXT_KEY_CIV_INDIA_SHORT_DESC CivAdjective=TXT_KEY_CIV_INDIA_ADJECTIVE FlagDecal=Art/Interface/TeamColor/FlagDECAL_WheelOfLaw.dds WhiteFlag=0 CivType=CIVILIZATION_INDIA Color=PLAYERCOLOR_PURPLE ArtStyle=ARTSTYLE_ASIAN PlayableCiv=1 MinorNationStatus=0 StartingGold=100 StartingX=87,StartingY=61 StateReligion= StartingEra=ERA_ANCIENT RandomStartLocation=false CivicOption=CIVICOPTION_GOVERNMENT, Civic=CIVIC_DESPOTISM CivicOption=CIVICOPTION_LEGAL, Civic=CIVIC_BARBARISM CivicOption=CIVICOPTION_LABOR, Civic=CIVIC_TRIBALISM CivicOption=CIVICOPTION_ECONOMY, Civic=CIVIC_DECENTRALIZATION CivicOption=CIVICOPTION_RELIGION, Civic=CIVIC_PAGANISM Handicap=HANDICAP_NOBLE EndPlayer BeginPlayer Team=4 LeaderType=LEADER_CATHERINE LeaderName=Catherine CivDesc=Russian Empire CivShortDesc=TXT_KEY_CIV_RUSSIA_SHORT_DESC CivAdjective=TXT_KEY_CIV_RUSSIA_ADJECTIVE FlagDecal=Art/Interface/TeamColor/FlagDECAL_DoubleEagle.dds WhiteFlag=0 CivType=CIVILIZATION_RUSSIA Color=PLAYERCOLOR_DARK_RED ArtStyle=ARTSTYLE_EUROPEAN PlayableCiv=1 MinorNationStatus=0 StartingGold=100 StartingX=49,StartingY=41 StateReligion= StartingEra=ERA_ANCIENT RandomStartLocation=false CivicOption=CIVICOPTION_GOVERNMENT, Civic=CIVIC_DESPOTISM CivicOption=CIVICOPTION_LEGAL, Civic=CIVIC_BARBARISM CivicOption=CIVICOPTION_LABOR, Civic=CIVIC_TRIBALISM CivicOption=CIVICOPTION_ECONOMY, Civic=CIVIC_DECENTRALIZATION CivicOption=CIVICOPTION_RELIGION, Civic=CIVIC_PAGANISM Handicap=HANDICAP_NOBLE EndPlayer BeginPlayer Team=5 LeaderType=LEADER_CYRUS LeaderName=Cyrus CivDesc=Persian Empire CivShortDesc=TXT_KEY_CIV_PERSIA_SHORT_DESC CivAdjective=TXT_KEY_CIV_PERSIA_ADJECTIVE FlagDecal=Art/Interface/TeamColor/FlagDECAL_Scimitar.dds WhiteFlag=0 CivType=CIVILIZATION_PERSIA Color=PLAYERCOLOR_CYAN ArtStyle=ARTSTYLE_MIDDLE_EAST PlayableCiv=1 MinorNationStatus=0 StartingGold=100 StartingX=70,StartingY=27 StateReligion= StartingEra=ERA_ANCIENT RandomStartLocation=false CivicOption=CIVICOPTION_GOVERNMENT, Civic=CIVIC_DESPOTISM CivicOption=CIVICOPTION_LEGAL, Civic=CIVIC_BARBARISM CivicOption=CIVICOPTION_LABOR, Civic=CIVIC_TRIBALISM CivicOption=CIVICOPTION_ECONOMY, Civic=CIVIC_DECENTRALIZATION CivicOption=CIVICOPTION_RELIGION, Civic=CIVIC_PAGANISM Handicap=HANDICAP_NOBLE EndPlayer BeginPlayer Team=6 LeaderType=LEADER_ELIZABETH LeaderName=Elizabeth CivDesc=English Empire CivShortDesc=TXT_KEY_CIV_ENGLAND_SHORT_DESC CivAdjective=TXT_KEY_CIV_ENGLAND_ADJECTIVE FlagDecal=Art/Interface/TeamColor/FlagDECAL_StGeorgeCross.dds WhiteFlag=0 CivType=CIVILIZATION_ENGLAND Color=PLAYERCOLOR_WHITE ArtStyle=ARTSTYLE_EUROPEAN PlayableCiv=1 MinorNationStatus=0 StartingGold=100 StartingX=69,StartingY=41 StateReligion= StartingEra=ERA_ANCIENT RandomStartLocation=false CivicOption=CIVICOPTION_GOVERNMENT, Civic=CIVIC_DESPOTISM CivicOption=CIVICOPTION_LEGAL, Civic=CIVIC_BARBARISM CivicOption=CIVICOPTION_LABOR, Civic=CIVIC_TRIBALISM CivicOption=CIVICOPTION_ECONOMY, Civic=CIVIC_DECENTRALIZATION CivicOption=CIVICOPTION_RELIGION, Civic=CIVIC_PAGANISM Handicap=HANDICAP_NOBLE EndPlayer BeginPlayer Team=7 LeaderType=LEADER_FREDERICK LeaderName=Frederick CivDesc=German Empire CivShortDesc=TXT_KEY_CIV_GERMANY_SHORT_DESC CivAdjective=TXT_KEY_CIV_GERMANY_ADJECTIVE FlagDecal=Art/Interface/TeamColor/FlagDECAL_MalteseCross.dds WhiteFlag=0 CivType=CIVILIZATION_GERMANY Color=PLAYERCOLOR_GRAY ArtStyle=ARTSTYLE_EUROPEAN PlayableCiv=1 MinorNationStatus=0 StartingGold=100 StartingX=49,StartingY=61 StateReligion= StartingEra=ERA_ANCIENT RandomStartLocation=false CivicOption=CIVICOPTION_GOVERNMENT, Civic=CIVIC_DESPOTISM CivicOption=CIVICOPTION_LEGAL, Civic=CIVIC_BARBARISM CivicOption=CIVICOPTION_LABOR, Civic=CIVIC_TRIBALISM CivicOption=CIVICOPTION_ECONOMY, Civic=CIVIC_DECENTRALIZATION CivicOption=CIVICOPTION_RELIGION, Civic=CIVIC_PAGANISM Handicap=HANDICAP_NOBLE EndPlayer BeginPlayer Team=8 LeaderType=LEADER_GENGHIS_KHAN LeaderName=Genghis Khan CivDesc=Mongolian Empire CivShortDesc=TXT_KEY_CIV_MONGOL_SHORT_DESC CivAdjective=TXT_KEY_CIV_MONGOL_ADJECTIVE FlagDecal=Art/Interface/TeamColor/FlagDECAL_Horse.dds WhiteFlag=0 CivType=CIVILIZATION_MONGOL Color=PLAYERCOLOR_BROWN ArtStyle=ARTSTYLE_ASIAN PlayableCiv=1 MinorNationStatus=0 StartingGold=100 StartingX=87,StartingY=41 StateReligion= StartingEra=ERA_ANCIENT RandomStartLocation=false CivicOption=CIVICOPTION_GOVERNMENT, Civic=CIVIC_DESPOTISM CivicOption=CIVICOPTION_LEGAL, Civic=CIVIC_BARBARISM CivicOption=CIVICOPTION_LABOR, Civic=CIVIC_TRIBALISM CivicOption=CIVICOPTION_ECONOMY, Civic=CIVIC_DECENTRALIZATION CivicOption=CIVICOPTION_RELIGION, Civic=CIVIC_PAGANISM Handicap=HANDICAP_NOBLE EndPlayer BeginPlayer Team=9 LeaderType=LEADER_HATSHEPSUT LeaderName=Hatshepsut CivDesc=Egyptian Empire CivShortDesc=TXT_KEY_CIV_EGYPT_SHORT_DESC CivAdjective=TXT_KEY_CIV_EGYPT_ADJECTIVE FlagDecal=Art/Interface/TeamColor/FlagDECAL_EyeOfRa.dds WhiteFlag=0 CivType=CIVILIZATION_EGYPT Color=PLAYERCOLOR_YELLOW ArtStyle=ARTSTYLE_MIDDLE_EAST PlayableCiv=1 MinorNationStatus=0 StartingGold=100 StartingX=50,StartingY=7 StateReligion= StartingEra=ERA_ANCIENT RandomStartLocation=false CivicOption=CIVICOPTION_GOVERNMENT, Civic=CIVIC_DESPOTISM CivicOption=CIVICOPTION_LEGAL, Civic=CIVIC_BARBARISM CivicOption=CIVICOPTION_LABOR, Civic=CIVIC_TRIBALISM CivicOption=CIVICOPTION_ECONOMY, Civic=CIVIC_DECENTRALIZATION CivicOption=CIVICOPTION_RELIGION, Civic=CIVIC_PAGANISM Handicap=HANDICAP_NOBLE EndPlayer BeginPlayer Team=10 LeaderType=LEADER_HUAYNA_CAPAC LeaderName=Huayna Capac CivDesc=Incan Empire CivShortDesc=TXT_KEY_CIV_INCA_SHORT_DESC CivAdjective=TXT_KEY_CIV_INCA_ADJECTIVE FlagDecal=Art/Interface/TeamColor/FlagDECAL_Sun.dds WhiteFlag=0 CivType=CIVILIZATION_INCA Color=PLAYERCOLOR_DARK_YELLOW ArtStyle=ARTSTYLE_SOUTH_AMERICA PlayableCiv=1 MinorNationStatus=0 StartingGold=100 StartingX=107,StartingY=8 StateReligion= StartingEra=ERA_ANCIENT RandomStartLocation=false CivicOption=CIVICOPTION_GOVERNMENT, Civic=CIVIC_DESPOTISM CivicOption=CIVICOPTION_LEGAL, Civic=CIVIC_BARBARISM CivicOption=CIVICOPTION_LABOR, Civic=CIVIC_TRIBALISM CivicOption=CIVICOPTION_ECONOMY, Civic=CIVIC_DECENTRALIZATION CivicOption=CIVICOPTION_RELIGION, Civic=CIVIC_PAGANISM Handicap=HANDICAP_NOBLE EndPlayer BeginPlayer Team=11 LeaderType=LEADER_ISABELLA LeaderName=Isabella CivDesc=Spanish Empire CivShortDesc=TXT_KEY_CIV_SPAIN_SHORT_DESC CivAdjective=TXT_KEY_CIV_SPAIN_ADJECTIVE FlagDecal=Art/Interface/TeamColor/FlagDECAL_Castle.dds WhiteFlag=0 CivType=CIVILIZATION_SPAIN Color=PLAYERCOLOR_PINK ArtStyle=ARTSTYLE_EUROPEAN PlayableCiv=1 MinorNationStatus=0 StartingGold=100 StartingX=87,StartingY=28 StateReligion= StartingEra=ERA_ANCIENT RandomStartLocation=false CivicOption=CIVICOPTION_GOVERNMENT, Civic=CIVIC_DESPOTISM CivicOption=CIVICOPTION_LEGAL, Civic=CIVIC_BARBARISM CivicOption=CIVICOPTION_LABOR, Civic=CIVIC_TRIBALISM CivicOption=CIVICOPTION_ECONOMY, Civic=CIVIC_DECENTRALIZATION CivicOption=CIVICOPTION_RELIGION, Civic=CIVIC_PAGANISM Handicap=HANDICAP_NOBLE EndPlayer BeginPlayer Team=12 LeaderType=LEADER_LOUIS_XIV LeaderName=Louis XIV CivDesc=French Empire CivShortDesc=TXT_KEY_CIV_FRANCE_SHORT_DESC CivAdjective=TXT_KEY_CIV_FRANCE_ADJECTIVE FlagDecal=Art/Interface/TeamColor/FlagDECAL_FleurDeLis.dds WhiteFlag=0 CivType=CIVILIZATION_FRANCE Color=PLAYERCOLOR_DARK_BLUE ArtStyle=ARTSTYLE_EUROPEAN PlayableCiv=1 MinorNationStatus=0 StartingGold=100 StartingX=69,StartingY=61 StateReligion= StartingEra=ERA_ANCIENT RandomStartLocation=false CivicOption=CIVICOPTION_GOVERNMENT, Civic=CIVIC_DESPOTISM CivicOption=CIVICOPTION_LEGAL, Civic=CIVIC_BARBARISM CivicOption=CIVICOPTION_LABOR, Civic=CIVIC_TRIBALISM CivicOption=CIVICOPTION_ECONOMY, Civic=CIVIC_DECENTRALIZATION CivicOption=CIVICOPTION_RELIGION, Civic=CIVIC_PAGANISM Handicap=HANDICAP_NOBLE EndPlayer BeginPlayer Team=13 LeaderType=LEADER_MANSA_MUSA LeaderName=Mansa Musa CivDesc=Malinese Empire CivShortDesc=TXT_KEY_CIV_MALI_SHORT_DESC CivAdjective=TXT_KEY_CIV_MALI_ADJECTIVE FlagDecal=Art/Interface/TeamColor/FlagDECAL_Mask.dds WhiteFlag=0 CivType=CIVILIZATION_MALI Color=PLAYERCOLOR_PEACH ArtStyle=ARTSTYLE_MIDDLE_EAST PlayableCiv=1 MinorNationStatus=0 StartingGold=100 StartingX=107,StartingY=28 StateReligion= StartingEra=ERA_ANCIENT RandomStartLocation=false CivicOption=CIVICOPTION_GOVERNMENT, Civic=CIVIC_DESPOTISM CivicOption=CIVICOPTION_LEGAL, Civic=CIVIC_BARBARISM CivicOption=CIVICOPTION_LABOR, Civic=CIVIC_TRIBALISM CivicOption=CIVICOPTION_ECONOMY, Civic=CIVIC_DECENTRALIZATION CivicOption=CIVICOPTION_RELIGION, Civic=CIVIC_PAGANISM Handicap=HANDICAP_NOBLE EndPlayer BeginPlayer Team=14 LeaderType=LEADER_MONTEZUMA LeaderName=Montezuma CivDesc=Aztec Empire CivShortDesc=TXT_KEY_CIV_AZTEC_SHORT_DESC CivAdjective=TXT_KEY_CIV_AZTEC_ADJECTIVE FlagDecal=Art/Interface/TeamColor/FlagDECAL_AztecCalendar.dds WhiteFlag=0 CivType=CIVILIZATION_AZTEC Color=PLAYERCOLOR_GREEN ArtStyle=ARTSTYLE_SOUTH_AMERICA PlayableCiv=1 MinorNationStatus=0 StartingGold=0 StartingX=87,StartingY=8 StateReligion= StartingEra=ERA_ANCIENT RandomStartLocation=false CivicOption=CIVICOPTION_GOVERNMENT, Civic=CIVIC_DESPOTISM CivicOption=CIVICOPTION_LEGAL, Civic=CIVIC_BARBARISM CivicOption=CIVICOPTION_LABOR, Civic=CIVIC_TRIBALISM CivicOption=CIVICOPTION_ECONOMY, Civic=CIVIC_DECENTRALIZATION CivicOption=CIVICOPTION_RELIGION, Civic=CIVIC_PAGANISM Handicap=HANDICAP_NOBLE EndPlayer BeginPlayer Team=15 LeaderType=LEADER_QIN_SHI_HUANG LeaderName=Qin Shi Huang CivDesc=Chinese Empire CivShortDesc=TXT_KEY_CIV_CHINA_SHORT_DESC CivAdjective=TXT_KEY_CIV_CHINA_ADJECTIVE FlagDecal=Art/Interface/TeamColor/FlagDECAL_Dragon.dds WhiteFlag=0 CivType=CIVILIZATION_CHINA Color=PLAYERCOLOR_DARK_PINK ArtStyle=ARTSTYLE_ASIAN PlayableCiv=1 MinorNationStatus=0 StartingGold=100 StartingX=107,StartingY=61 StateReligion= StartingEra=ERA_ANCIENT RandomStartLocation=false CivicOption=CIVICOPTION_GOVERNMENT, Civic=CIVIC_DESPOTISM CivicOption=CIVICOPTION_LEGAL, Civic=CIVIC_BARBARISM CivicOption=CIVICOPTION_LABOR, Civic=CIVIC_TRIBALISM CivicOption=CIVICOPTION_ECONOMY, Civic=CIVIC_DECENTRALIZATION CivicOption=CIVICOPTION_RELIGION, Civic=CIVIC_PAGANISM Handicap=HANDICAP_NOBLE EndPlayer BeginPlayer Team=16 LeaderType=LEADER_SALADIN LeaderName=Saladin CivDesc=Arabian Empire CivShortDesc=TXT_KEY_CIV_ARABIA_SHORT_DESC CivAdjective=TXT_KEY_CIV_ARABIA_ADJECTIVE FlagDecal=Art/Interface/TeamColor/FlagDECAL_Arabic.dds WhiteFlag=0 CivType=CIVILIZATION_ARABIA Color=PLAYERCOLOR_LIGHT_GREEN ArtStyle=ARTSTYLE_MIDDLE_EAST PlayableCiv=1 MinorNationStatus=0 StartingGold=100 StartingX=70,StartingY=7 StateReligion= StartingEra=ERA_ANCIENT RandomStartLocation=false CivicOption=CIVICOPTION_GOVERNMENT, Civic=CIVIC_DESPOTISM CivicOption=CIVICOPTION_LEGAL, Civic=CIVIC_BARBARISM CivicOption=CIVICOPTION_LABOR, Civic=CIVIC_TRIBALISM CivicOption=CIVICOPTION_ECONOMY, Civic=CIVIC_DECENTRALIZATION CivicOption=CIVICOPTION_RELIGION, Civic=CIVIC_PAGANISM Handicap=HANDICAP_NOBLE EndPlayer BeginPlayer Team=17 LeaderType=LEADER_TOKUGAWA LeaderName=Tokugawa CivDesc=Japanese Empire CivShortDesc=TXT_KEY_CIV_JAPAN_SHORT_DESC CivAdjective=TXT_KEY_CIV_JAPAN_ADJECTIVE FlagDecal=Art/Interface/TeamColor/FlagDECAL_Dot.dds WhiteFlag=0 CivType=CIVILIZATION_JAPAN Color=PLAYERCOLOR_RED ArtStyle=ARTSTYLE_ASIAN PlayableCiv=1 MinorNationStatus=0 StartingGold=100 StartingX=107,StartingY=41 StateReligion= StartingEra=ERA_ANCIENT RandomStartLocation=false CivicOption=CIVICOPTION_GOVERNMENT, Civic=CIVIC_DESPOTISM CivicOption=CIVICOPTION_LEGAL, Civic=CIVIC_BARBARISM CivicOption=CIVICOPTION_LABOR, Civic=CIVIC_TRIBALISM CivicOption=CIVICOPTION_ECONOMY, Civic=CIVIC_DECENTRALIZATION CivicOption=CIVICOPTION_RELIGION, Civic=CIVIC_PAGANISM Handicap=HANDICAP_NOBLE EndPlayer
A3: BeginTeam TeamID=17 Tech=TECH_HUNTING Tech=TECH_AGRICULTURE ContactWithTeam=1 RevealMap=0 EndTeam | B3: BeginPlayer Team=17 LeaderType=LEADER_FRANKLIN_ROOSEVELT LeaderName=Jack CivDesc=American Empire CivShortDesc=TXT_KEY_CIV_AMERICA_SHORT_DESC CivAdjective=TXT_KEY_CIV_AMERICA_ADJECTIVE FlagDecal=Art/Interface/TeamColor/FlagDECAL_Star.dds WhiteFlag=0 CivType=CIVILIZATION_AMERICA Color=PLAYERCOLOR_BLUE ArtStyle=ARTSTYLE_EUROPEAN PlayableCiv=1 MinorNationStatus=0 StartingGold=100 StartingX=25, StartingY=37 StateReligion= StartingEra=ERA_ANCIENT RandomStartLocation=false CivicOption=CIVICOPTION_GOVERNMENT, Civic=CIVIC_DESPOTISM CivicOption=CIVICOPTION_LEGAL, Civic=CIVIC_BARBARISM CivicOption=CIVICOPTION_LABOR, Civic=CIVIC_TRIBALISM CivicOption=CIVICOPTION_ECONOMY, Civic=CIVIC_DECENTRALIZATION CivicOption=CIVICOPTION_RELIGION, Civic=CIVIC_PAGANISM Handicap=HANDICAP_NOBLE EndPlayer | C3: =MID(B3, SEARCH("_", B3) + 1, SEARCH("LeaderName", B3) - SEARCH("_", B3) - 3) -> FRANKLIN_ROOSEVELT | D3: 0 | E3: {=INDEX('plot type'!EC$2:EC$19, MATCH(SUBSTITUTE($C3, "_", " "), UPPER('plot type'!$EE$2:$EE$19), 0))} -> 25 | F3: {=INDEX('plot type'!ED$2:ED$19, MATCH(SUBSTITUTE($C3, "_", " "), UPPER('plot type'!$EE$2:$EE$19), 0))} -> 37 | G3: =MID(B3, SEARCH("startingx", B3), SEARCH(CHAR(10), B3, SEARCH("startingx", B3)) - SEARCH("startingx", B3)) -> StartingX=25, StartingY=37 | I3: =LEFT(A3, SEARCH("=", A3)) & D3 & MID(A3, SEARCH("Tech", A3) - 2, LEN(A3)) -> BeginTeam TeamID=0 Tech=TECH_HUNTING Tech=TECH_AGRICULTURE ContactWithTeam=1 RevealMap=0 EndTeam | J3: =LEFT(B3, SEARCH("=", B3)) & D3 & SUBSTITUTE(MID(B3, SEARCH("LeaderType", B3) - 2, LEN(B3)), G3, "StartingX=" & E3 & ",StartingY=" & F3) -> BeginPlayer Team=0 LeaderType=LEADER_FRANKLIN_ROOSEVELT LeaderName=Jack CivDesc=American Empire CivShortDesc=TXT_KEY_CIV_AMERICA_SHORT_DESC CivAdjective=TXT_KEY_CIV_AMERICA_ADJECTIVE FlagDecal=Art/Interface/TeamColor/FlagDECAL_Star.dds WhiteFlag=0 CivType=CIVILIZATION_AMERICA Color=PLAYERCOLOR_BLUE ArtStyle=ARTSTYLE_EUROPEAN PlayableCiv=1 MinorNationStatus=0 StartingGold=100 StartingX=25,StartingY=37 StateReligion= StartingEra=ERA_ANCIENT RandomStartLocation=false CivicOption=CIVICOPTION_GOVERNMENT, Civic=CIVIC_DESPOTISM CivicOption=CIVICOPTION_LEGAL, Civic=CIVIC_BARBARISM CivicOption=CIVICOPTION_LABOR, Civic=CIVIC_TRIBALISM CivicOption=CIVICOPTION_ECONOMY, Civic=CIVIC_DECENTRALIZATION CivicOption=CIVICOPTION_RELIGION, Civic=CIVIC_PAGANISM Handicap=HANDICAP_NOBLE EndPlayer
A4: BeginTeam TeamID=4 Tech=TECH_HUNTING Tech=TECH_AGRICULTURE ContactWithTeam=0 RevealMap=0 EndTeam | B4: BeginPlayer Team=4 LeaderType=LEADER_JULIUS_CAESAR LeaderName=Julius Caesar CivDesc=Roman Empire CivShortDesc=TXT_KEY_CIV_ROME_SHORT_DESC CivAdjective=TXT_KEY_CIV_ROME_ADJECTIVE FlagDecal=Art/Interface/TeamColor/FlagDECAL_Laurels.dds WhiteFlag=0 CivType=CIVILIZATION_ROME Color=PLAYERCOLOR_DARK_PURPLE ArtStyle=ARTSTYLE_GRECO_ROMAN PlayableCiv=1 MinorNationStatus=0 StartingGold=100 StartingX=22, StartingY=17 StateReligion= StartingEra=ERA_ANCIENT RandomStartLocation=false CivicOption=CIVICOPTION_GOVERNMENT, Civic=CIVIC_DESPOTISM CivicOption=CIVICOPTION_LEGAL, Civic=CIVIC_BARBARISM CivicOption=CIVICOPTION_LABOR, Civic=CIVIC_TRIBALISM CivicOption=CIVICOPTION_ECONOMY, Civic=CIVIC_DECENTRALIZATION CivicOption=CIVICOPTION_RELIGION, Civic=CIVIC_PAGANISM Handicap=HANDICAP_NOBLE EndPlayer | C4: =MID(B4, SEARCH("_", B4) + 1, SEARCH("LeaderName", B4) - SEARCH("_", B4) - 3) -> JULIUS_CAESAR | D4: 1 | E4: {=INDEX('plot type'!EC$2:EC$19, MATCH(SUBSTITUTE($C4, "_", " "), UPPER('plot type'!$EE$2:$EE$19), 0))} -> 22 | F4: {=INDEX('plot type'!ED$2:ED$19, MATCH(SUBSTITUTE($C4, "_", " "), UPPER('plot type'!$EE$2:$EE$19), 0))} -> 17 | G4: =MID(B4, SEARCH("startingx", B4), SEARCH(CHAR(10), B4, SEARCH("startingx", B4)) - SEARCH("startingx", B4)) -> StartingX=22, StartingY=17 | I4: =LEFT(A4, SEARCH("=", A4)) & D4 & MID(A4, SEARCH("Tech", A4) - 2, LEN(A4)) -> BeginTeam TeamID=1 Tech=TECH_HUNTING Tech=TECH_AGRICULTURE ContactWithTeam=0 RevealMap=0 EndTeam | J4: =LEFT(B4, SEARCH("=", B4)) & D4 & SUBSTITUTE(MID(B4, SEARCH("LeaderType", B4) - 2, LEN(B4)), G4, "StartingX=" & E4 & ",StartingY=" & F4) -> BeginPlayer Team=1 LeaderType=LEADER_JULIUS_CAESAR LeaderName=Julius Caesar CivDesc=Roman Empire CivShortDesc=TXT_KEY_CIV_ROME_SHORT_DESC CivAdjective=TXT_KEY_CIV_ROME_ADJECTIVE FlagDecal=Art/Interface/TeamColor/FlagDECAL_Laurels.dds WhiteFlag=0 CivType=CIVILIZATION_ROME Color=PLAYERCOLOR_DARK_PURPLE ArtStyle=ARTSTYLE_GRECO_ROMAN PlayableCiv=1 MinorNationStatus=0 StartingGold=100 StartingX=22,StartingY=17 StateReligion= StartingEra=ERA_ANCIENT RandomStartLocation=false CivicOption=CIVICOPTION_GOVERNMENT, Civic=CIVIC_DESPOTISM CivicOption=CIVICOPTION_LEGAL, Civic=CIVIC_BARBARISM CivicOption=CIVICOPTION_LABOR, Civic=CIVIC_TRIBALISM CivicOption=CIVICOPTION_ECONOMY, Civic=CIVIC_DECENTRALIZATION CivicOption=CIVICOPTION_RELIGION, Civic=CIVIC_PAGANISM Handicap=HANDICAP_NOBLE EndPlayer
A5: BeginTeam TeamID=3 Tech=TECH_FISHING Tech=TECH_HUNTING EspionageTeam=5, EspionageAmount=5 EspionageEverAmount=9 RevealMap=0 EndTeam | B5: BeginPlayer Team=3 LeaderType=LEADER_ALEXANDER LeaderName=Alexander CivDesc=Greek Empire CivShortDesc=TXT_KEY_CIV_GREECE_SHORT_DESC CivAdjective=TXT_KEY_CIV_GREECE_ADJECTIVE FlagDecal=Art/Interface/TeamColor/FlagDECAL_Helmet.dds WhiteFlag=0 CivType=CIVILIZATION_GREECE Color=PLAYERCOLOR_LIGHT_BLUE ArtStyle=ARTSTYLE_GRECO_ROMAN PlayableCiv=1 MinorNationStatus=0 StartingGold=100 StartingX=67, StartingY=6 StateReligion= StartingEra=ERA_ANCIENT RandomStartLocation=false CivicOption=CIVICOPTION_GOVERNMENT, Civic=CIVIC_DESPOTISM CivicOption=CIVICOPTION_LEGAL, Civic=CIVIC_BARBARISM CivicOption=CIVICOPTION_LABOR, Civic=CIVIC_TRIBALISM CivicOption=CIVICOPTION_ECONOMY, Civic=CIVIC_DECENTRALIZATION CivicOption=CIVICOPTION_RELIGION, Civic=CIVIC_PAGANISM Handicap=HANDICAP_NOBLE EndPlayer | C5: =MID(B5, SEARCH("_", B5) + 1, SEARCH("LeaderName", B5) - SEARCH("_", B5) - 3) -> ALEXANDER | D5: 2 | E5: {=INDEX('plot type'!EC$2:EC$19, MATCH(SUBSTITUTE($C5, "_", " "), UPPER('plot type'!$EE$2:$EE$19), 0))} -> 50 | F5: {=INDEX('plot type'!ED$2:ED$19, MATCH(SUBSTITUTE($C5, "_", " "), UPPER('plot type'!$EE$2:$EE$19), 0))} -> 27 | G5: =MID(B5, SEARCH("startingx", B5), SEARCH(CHAR(10), B5, SEARCH("startingx", B5)) - SEARCH("startingx", B5)) -> StartingX=67, StartingY=6 | I5: =LEFT(A5, SEARCH("=", A5)) & D5 & MID(A5, SEARCH("Tech", A5) - 2, LEN(A5)) -> BeginTeam TeamID=2 Tech=TECH_FISHING Tech=TECH_HUNTING EspionageTeam=5, EspionageAmount=5 EspionageEverAmount=9 RevealMap=0 EndTeam | J5: =LEFT(B5, SEARCH("=", B5)) & D5 & SUBSTITUTE(MID(B5, SEARCH("LeaderType", B5) - 2, LEN(B5)), G5, "StartingX=" & E5 & ",StartingY=" & F5) -> BeginPlayer Team=2 LeaderType=LEADER_ALEXANDER LeaderName=Alexander CivDesc=Greek Empire CivShortDesc=TXT_KEY_CIV_GREECE_SHORT_DESC CivAdjective=TXT_KEY_CIV_GREECE_ADJECTIVE FlagDecal=Art/Interface/TeamColor/FlagDECAL_Helmet.dds WhiteFlag=0 CivType=CIVILIZATION_GREECE Color=PLAYERCOLOR_LIGHT_BLUE ArtStyle=ARTSTYLE_GRECO_ROMAN PlayableCiv=1 MinorNationStatus=0 StartingGold=100 StartingX=50,StartingY=27 StateReligion= StartingEra=ERA_ANCIENT RandomStartLocation=false CivicOption=CIVICOPTION_GOVERNMENT, Civic=CIVIC_DESPOTISM CivicOption=CIVICOPTION_LEGAL, Civic=CIVIC_BARBARISM CivicOption=CIVICOPTION_LABOR, Civic=CIVIC_TRIBALISM CivicOption=CIVICOPTION_ECONOMY, Civic=CIVIC_DECENTRALIZATION CivicOption=CIVICOPTION_RELIGION, Civic=CIVIC_PAGANISM Handicap=HANDICAP_NOBLE EndPlayer
A6: BeginTeam TeamID=1 Tech=TECH_MYSTICISM Tech=TECH_MINING EspionageTeam=10, EspionageAmount=4 EspionageEverAmount=8 RevealMap=0 EndTeam | B6: BeginPlayer Team=1 LeaderType=LEADER_ASOKA LeaderName=Asoka CivDesc=Indian Empire CivShortDesc=TXT_KEY_CIV_INDIA_SHORT_DESC CivAdjective=TXT_KEY_CIV_INDIA_ADJECTIVE FlagDecal=Art/Interface/TeamColor/FlagDECAL_WheelOfLaw.dds WhiteFlag=0 CivType=CIVILIZATION_INDIA Color=PLAYERCOLOR_PURPLE ArtStyle=ARTSTYLE_ASIAN PlayableCiv=1 MinorNationStatus=0 StartingGold=100 StartingX=90, StartingY=40 StateReligion= StartingEra=ERA_ANCIENT RandomStartLocation=false CivicOption=CIVICOPTION_GOVERNMENT, Civic=CIVIC_DESPOTISM CivicOption=CIVICOPTION_LEGAL, Civic=CIVIC_BARBARISM CivicOption=CIVICOPTION_LABOR, Civic=CIVIC_TRIBALISM CivicOption=CIVICOPTION_ECONOMY, Civic=CIVIC_DECENTRALIZATION CivicOption=CIVICOPTION_RELIGION, Civic=CIVIC_PAGANISM Handicap=HANDICAP_NOBLE EndPlayer | C6: =MID(B6, SEARCH("_", B6) + 1, SEARCH("LeaderName", B6) - SEARCH("_", B6) - 3) -> ASOKA | D6: 3 | E6: {=INDEX('plot type'!EC$2:EC$19, MATCH(SUBSTITUTE($C6, "_", " "), UPPER('plot type'!$EE$2:$EE$19), 0))} -> 87 | F6: {=INDEX('plot type'!ED$2:ED$19, MATCH(SUBSTITUTE($C6, "_", " "), UPPER('plot type'!$EE$2:$EE$19), 0))} -> 61 | G6: =MID(B6, SEARCH("startingx", B6), SEARCH(CHAR(10), B6, SEARCH("startingx", B6)) - SEARCH("startingx", B6)) -> StartingX=90, StartingY=40 | I6: =LEFT(A6, SEARCH("=", A6)) & D6 & MID(A6, SEARCH("Tech", A6) - 2, LEN(A6)) -> BeginTeam TeamID=3 Tech=TECH_MYSTICISM Tech=TECH_MINING EspionageTeam=10, EspionageAmount=4 EspionageEverAmount=8 RevealMap=0 EndTeam | J6: =LEFT(B6, SEARCH("=", B6)) & D6 & SUBSTITUTE(MID(B6, SEARCH("LeaderType", B6) - 2, LEN(B6)), G6, "StartingX=" & E6 & ",StartingY=" & F6) -> BeginPlayer Team=3 LeaderType=LEADER_ASOKA LeaderName=Asoka CivDesc=Indian Empire CivShortDesc=TXT_KEY_CIV_INDIA_SHORT_DESC CivAdjective=TXT_KEY_CIV_INDIA_ADJECTIVE FlagDecal=Art/Interface/TeamColor/FlagDECAL_WheelOfLaw.dds WhiteFlag=0 CivType=CIVILIZATION_INDIA Color=PLAYERCOLOR_PURPLE ArtStyle=ARTSTYLE_ASIAN PlayableCiv=1 MinorNationStatus=0 StartingGold=100 StartingX=87,StartingY=61 StateReligion= StartingEra=ERA_ANCIENT RandomStartLocation=false CivicOption=CIVICOPTION_GOVERNMENT, Civic=CIVIC_DESPOTISM CivicOption=CIVICOPTION_LEGAL, Civic=CIVIC_BARBARISM CivicOption=CIVICOPTION_LABOR, Civic=CIVIC_TRIBALISM CivicOption=CIVICOPTION_ECONOMY, Civic=CIVIC_DECENTRALIZATION CivicOption=CIVICOPTION_RELIGION, Civic=CIVIC_PAGANISM Handicap=HANDICAP_NOBLE EndPlayer
A7: BeginTeam TeamID=13 Tech=TECH_HUNTING Tech=TECH_MINING RevealMap=0 EndTeam | B7: BeginPlayer Team=13 LeaderType=LEADER_CATHERINE LeaderName=Catherine CivDesc=Russian Empire CivShortDesc=TXT_KEY_CIV_RUSSIA_SHORT_DESC CivAdjective=TXT_KEY_CIV_RUSSIA_ADJECTIVE FlagDecal=Art/Interface/TeamColor/FlagDECAL_DoubleEagle.dds WhiteFlag=0 CivType=CIVILIZATION_RUSSIA Color=PLAYERCOLOR_DARK_RED ArtStyle=ARTSTYLE_EUROPEAN PlayableCiv=1 MinorNationStatus=0 StartingGold=100 StartingX=87, StartingY=54 StateReligion= StartingEra=ERA_ANCIENT RandomStartLocation=false CivicOption=CIVICOPTION_GOVERNMENT, Civic=CIVIC_DESPOTISM CivicOption=CIVICOPTION_LEGAL, Civic=CIVIC_BARBARISM CivicOption=CIVICOPTION_LABOR, Civic=CIVIC_TRIBALISM CivicOption=CIVICOPTION_ECONOMY, Civic=CIVIC_DECENTRALIZATION CivicOption=CIVICOPTION_RELIGION, Civic=CIVIC_PAGANISM Handicap=HANDICAP_NOBLE EndPlayer | C7: =MID(B7, SEARCH("_", B7) + 1, SEARCH("LeaderName", B7) - SEARCH("_", B7) - 3) -> CATHERINE | D7: 4 | E7: {=INDEX('plot type'!EC$2:EC$19, MATCH(SUBSTITUTE($C7, "_", " "), UPPER('plot type'!$EE$2:$EE$19), 0))} -> 49 | F7: {=INDEX('plot type'!ED$2:ED$19, MATCH(SUBSTITUTE($C7, "_", " "), UPPER('plot type'!$EE$2:$EE$19), 0))} -> 41 | G7: =MID(B7, SEARCH("startingx", B7), SEARCH(CHAR(10), B7, SEARCH("startingx", B7)) - SEARCH("startingx", B7)) -> StartingX=87, StartingY=54 | I7: =LEFT(A7, SEARCH("=", A7)) & D7 & MID(A7, SEARCH("Tech", A7) - 2, LEN(A7)) -> BeginTeam TeamID=4 Tech=TECH_HUNTING Tech=TECH_MINING RevealMap=0 EndTeam | J7: =LEFT(B7, SEARCH("=", B7)) & D7 & SUBSTITUTE(MID(B7, SEARCH("LeaderType", B7) - 2, LEN(B7)), G7, "StartingX=" & E7 & ",StartingY=" & F7) -> BeginPlayer Team=4 LeaderType=LEADER_CATHERINE LeaderName=Catherine CivDesc=Russian Empire CivShortDesc=TXT_KEY_CIV_RUSSIA_SHORT_DESC CivAdjective=TXT_KEY_CIV_RUSSIA_ADJECTIVE FlagDecal=Art/Interface/TeamColor/FlagDECAL_DoubleEagle.dds WhiteFlag=0 CivType=CIVILIZATION_RUSSIA Color=PLAYERCOLOR_DARK_RED ArtStyle=ARTSTYLE_EUROPEAN PlayableCiv=1 MinorNationStatus=0 StartingGold=100 StartingX=49,StartingY=41 StateReligion= StartingEra=ERA_ANCIENT RandomStartLocation=false CivicOption=CIVICOPTION_GOVERNMENT, Civic=CIVIC_DESPOTISM CivicOption=CIVICOPTION_LEGAL, Civic=CIVIC_BARBARISM CivicOption=CIVICOPTION_LABOR, Civic=CIVIC_TRIBALISM CivicOption=CIVICOPTION_ECONOMY, Civic=CIVIC_DECENTRALIZATION CivicOption=CIVICOPTION_RELIGION, Civic=CIVIC_PAGANISM Handicap=HANDICAP_NOBLE EndPlayer
A8: BeginTeam TeamID=5 Tech=TECH_AGRICULTURE Tech=TECH_HUNTING RevealMap=0 EndTeam | B8: BeginPlayer Team=5 LeaderType=LEADER_CYRUS LeaderName=Cyrus CivDesc=Persian Empire CivShortDesc=TXT_KEY_CIV_PERSIA_SHORT_DESC CivAdjective=TXT_KEY_CIV_PERSIA_ADJECTIVE FlagDecal=Art/Interface/TeamColor/FlagDECAL_Scimitar.dds WhiteFlag=0 CivType=CIVILIZATION_PERSIA Color=PLAYERCOLOR_CYAN ArtStyle=ARTSTYLE_MIDDLE_EAST PlayableCiv=1 MinorNationStatus=0 StartingGold=100 StartingX=98, StartingY=15 StateReligion= StartingEra=ERA_ANCIENT RandomStartLocation=false CivicOption=CIVICOPTION_GOVERNMENT, Civic=CIVIC_DESPOTISM CivicOption=CIVICOPTION_LEGAL, Civic=CIVIC_BARBARISM CivicOption=CIVICOPTION_LABOR, Civic=CIVIC_TRIBALISM CivicOption=CIVICOPTION_ECONOMY, Civic=CIVIC_DECENTRALIZATION CivicOption=CIVICOPTION_RELIGION, Civic=CIVIC_PAGANISM Handicap=HANDICAP_NOBLE EndPlayer | C8: =MID(B8, SEARCH("_", B8) + 1, SEARCH("LeaderName", B8) - SEARCH("_", B8) - 3) -> CYRUS | D8: 5 | E8: {=INDEX('plot type'!EC$2:EC$19, MATCH(SUBSTITUTE($C8, "_", " "), UPPER('plot type'!$EE$2:$EE$19), 0))} -> 70 | F8: {=INDEX('plot type'!ED$2:ED$19, MATCH(SUBSTITUTE($C8, "_", " "), UPPER('plot type'!$EE$2:$EE$19), 0))} -> 27 | G8: =MID(B8, SEARCH("startingx", B8), SEARCH(CHAR(10), B8, SEARCH("startingx", B8)) - SEARCH("startingx", B8)) -> StartingX=98, StartingY=15 | I8: =LEFT(A8, SEARCH("=", A8)) & D8 & MID(A8, SEARCH("Tech", A8) - 2, LEN(A8)) -> BeginTeam TeamID=5 Tech=TECH_AGRICULTURE Tech=TECH_HUNTING RevealMap=0 EndTeam | J8: =LEFT(B8, SEARCH("=", B8)) & D8 & SUBSTITUTE(MID(B8, SEARCH("LeaderType", B8) - 2, LEN(B8)), G8, "StartingX=" & E8 & ",StartingY=" & F8) -> BeginPlayer Team=5 LeaderType=LEADER_CYRUS LeaderName=Cyrus CivDesc=Persian Empire CivShortDesc=TXT_KEY_CIV_PERSIA_SHORT_DESC CivAdjective=TXT_KEY_CIV_PERSIA_ADJECTIVE FlagDecal=Art/Interface/TeamColor/FlagDECAL_Scimitar.dds WhiteFlag=0 CivType=CIVILIZATION_PERSIA Color=PLAYERCOLOR_CYAN ArtStyle=ARTSTYLE_MIDDLE_EAST PlayableCiv=1 MinorNationStatus=0 StartingGold=100 StartingX=70,StartingY=27 StateReligion= StartingEra=ERA_ANCIENT RandomStartLocation=false CivicOption=CIVICOPTION_GOVERNMENT, Civic=CIVIC_DESPOTISM CivicOption=CIVICOPTION_LEGAL, Civic=CIVIC_BARBARISM CivicOption=CIVICOPTION_LABOR, Civic=CIVIC_TRIBALISM CivicOption=CIVICOPTION_ECONOMY, Civic=CIVIC_DECENTRALIZATION CivicOption=CIVICOPTION_RELIGION, Civic=CIVIC_PAGANISM Handicap=HANDICAP_NOBLE EndPlayer
A9: BeginTeam TeamID=12 Tech=TECH_FISHING Tech=TECH_MINING RevealMap=0 EndTeam | B9: BeginPlayer Team=12 LeaderType=LEADER_ELIZABETH LeaderName=Elizabeth CivDesc=English Empire CivShortDesc=TXT_KEY_CIV_ENGLAND_SHORT_DESC CivAdjective=TXT_KEY_CIV_ENGLAND_ADJECTIVE FlagDecal=Art/Interface/TeamColor/FlagDECAL_StGeorgeCross.dds WhiteFlag=0 CivType=CIVILIZATION_ENGLAND Color=PLAYERCOLOR_WHITE ArtStyle=ARTSTYLE_EUROPEAN PlayableCiv=1 MinorNationStatus=0 StartingGold=100 StartingX=50, StartingY=61 StateReligion= StartingEra=ERA_ANCIENT RandomStartLocation=false CivicOption=CIVICOPTION_GOVERNMENT, Civic=CIVIC_DESPOTISM CivicOption=CIVICOPTION_LEGAL, Civic=CIVIC_BARBARISM CivicOption=CIVICOPTION_LABOR, Civic=CIVIC_TRIBALISM CivicOption=CIVICOPTION_ECONOMY, Civic=CIVIC_DECENTRALIZATION CivicOption=CIVICOPTION_RELIGION, Civic=CIVIC_PAGANISM Handicap=HANDICAP_NOBLE EndPlayer | C9: =MID(B9, SEARCH("_", B9) + 1, SEARCH("LeaderName", B9) - SEARCH("_", B9) - 3) -> ELIZABETH | D9: 6 | E9: {=INDEX('plot type'!EC$2:EC$19, MATCH(SUBSTITUTE($C9, "_", " "), UPPER('plot type'!$EE$2:$EE$19), 0))} -> 69 | F9: {=INDEX('plot type'!ED$2:ED$19, MATCH(SUBSTITUTE($C9, "_", " "), UPPER('plot type'!$EE$2:$EE$19), 0))} -> 41 | G9: =MID(B9, SEARCH("startingx", B9), SEARCH(CHAR(10), B9, SEARCH("startingx", B9)) - SEARCH("startingx", B9)) -> StartingX=50, StartingY=61 | I9: =LEFT(A9, SEARCH("=", A9)) & D9 & MID(A9, SEARCH("Tech", A9) - 2, LEN(A9)) -> BeginTeam TeamID=6 Tech=TECH_FISHING Tech=TECH_MINING RevealMap=0 EndTeam | J9: =LEFT(B9, SEARCH("=", B9)) & D9 & SUBSTITUTE(MID(B9, SEARCH("LeaderType", B9) - 2, LEN(B9)), G9, "StartingX=" & E9 & ",StartingY=" & F9) -> BeginPlayer Team=6 LeaderType=LEADER_ELIZABETH LeaderName=Elizabeth CivDesc=English Empire CivShortDesc=TXT_KEY_CIV_ENGLAND_SHORT_DESC CivAdjective=TXT_KEY_CIV_ENGLAND_ADJECTIVE FlagDecal=Art/Interface/TeamColor/FlagDECAL_StGeorgeCross.dds WhiteFlag=0 CivType=CIVILIZATION_ENGLAND Color=PLAYERCOLOR_WHITE ArtStyle=ARTSTYLE_EUROPEAN PlayableCiv=1 MinorNationStatus=0 StartingGold=100 StartingX=69,StartingY=41 StateReligion= StartingEra=ERA_ANCIENT RandomStartLocation=false CivicOption=CIVICOPTION_GOVERNMENT, Civic=CIVIC_DESPOTISM CivicOption=CIVICOPTION_LEGAL, Civic=CIVIC_BARBARISM CivicOption=CIVICOPTION_LABOR, Civic=CIVIC_TRIBALISM CivicOption=CIVICOPTION_ECONOMY, Civic=CIVIC_DECENTRALIZATION CivicOption=CIVICOPTION_RELIGION, Civic=CIVIC_PAGANISM Handicap=HANDICAP_NOBLE EndPlayer
A10: BeginTeam TeamID=7 Tech=TECH_HUNTING Tech=TECH_MINING RevealMap=0 EndTeam | B10: BeginPlayer Team=7 LeaderType=LEADER_FREDERICK LeaderName=Frederick CivDesc=German Empire CivShortDesc=TXT_KEY_CIV_GERMANY_SHORT_DESC CivAdjective=TXT_KEY_CIV_GERMANY_ADJECTIVE FlagDecal=Art/Interface/TeamColor/FlagDECAL_MalteseCross.dds WhiteFlag=0 CivType=CIVILIZATION_GERMANY Color=PLAYERCOLOR_GRAY ArtStyle=ARTSTYLE_EUROPEAN PlayableCiv=1 MinorNationStatus=0 StartingGold=100 StartingX=66, StartingY=58 StateReligion= StartingEra=ERA_ANCIENT RandomStartLocation=false CivicOption=CIVICOPTION_GOVERNMENT, Civic=CIVIC_DESPOTISM CivicOption=CIVICOPTION_LEGAL, Civic=CIVIC_BARBARISM CivicOption=CIVICOPTION_LABOR, Civic=CIVIC_TRIBALISM CivicOption=CIVICOPTION_ECONOMY, Civic=CIVIC_DECENTRALIZATION CivicOption=CIVICOPTION_RELIGION, Civic=CIVIC_PAGANISM Handicap=HANDICAP_NOBLE EndPlayer | C10: =MID(B10, SEARCH("_", B10) + 1, SEARCH("LeaderName", B10) - SEARCH("_", B10) - 3) -> FREDERICK | D10: 7 | E10: {=INDEX('plot type'!EC$2:EC$19, MATCH(SUBSTITUTE($C10, "_", " "), UPPER('plot type'!$EE$2:$EE$19), 0))} -> 49 | F10: {=INDEX('plot type'!ED$2:ED$19, MATCH(SUBSTITUTE($C10, "_", " "), UPPER('plot type'!$EE$2:$EE$19), 0))} -> 61 | G10: =MID(B10, SEARCH("startingx", B10), SEARCH(CHAR(10), B10, SEARCH("startingx", B10)) - SEARCH("startingx", B10)) -> StartingX=66, StartingY=58 | I10: =LEFT(A10, SEARCH("=", A10)) & D10 & MID(A10, SEARCH("Tech", A10) - 2, LEN(A10)) -> BeginTeam TeamID=7 Tech=TECH_HUNTING Tech=TECH_MINING RevealMap=0 EndTeam | J10: =LEFT(B10, SEARCH("=", B10)) & D10 & SUBSTITUTE(MID(B10, SEARCH("LeaderType", B10) - 2, LEN(B10)), G10, "StartingX=" & E10 & ",StartingY=" & F10) -> BeginPlayer Team=7 LeaderType=LEADER_FREDERICK LeaderName=Frederick CivDesc=German Empire CivShortDesc=TXT_KEY_CIV_GERMANY_SHORT_DESC CivAdjective=TXT_KEY_CIV_GERMANY_ADJECTIVE FlagDecal=Art/Interface/TeamColor/FlagDECAL_MalteseCross.dds WhiteFlag=0 CivType=CIVILIZATION_GERMANY Color=PLAYERCOLOR_GRAY ArtStyle=ARTSTYLE_EUROPEAN PlayableCiv=1 MinorNationStatus=0 StartingGold=100 StartingX=49,StartingY=61 StateReligion= StartingEra=ERA_ANCIENT RandomStartLocation=false CivicOption=CIVICOPTION_GOVERNMENT, Civic=CIVIC_DESPOTISM CivicOption=CIVICOPTION_LEGAL, Civic=CIVIC_BARBARISM CivicOption=CIVICOPTION_LABOR, Civic=CIVIC_TRIBALISM CivicOption=CIVICOPTION_ECONOMY, Civic=CIVIC_DECENTRALIZATION CivicOption=CIVICOPTION_RELIGION, Civic=CIVIC_PAGANISM Handicap=HANDICAP_NOBLE EndPlayer
A11: BeginTeam TeamID=8 Tech=TECH_THE_WHEEL Tech=TECH_HUNTING RevealMap=0 EndTeam | B11: BeginPlayer Team=8 LeaderType=LEADER_GENGHIS_KHAN LeaderName=Genghis Khan CivDesc=Mongolian Empire CivShortDesc=TXT_KEY_CIV_MONGOL_SHORT_DESC CivAdjective=TXT_KEY_CIV_MONGOL_ADJECTIVE FlagDecal=Art/Interface/TeamColor/FlagDECAL_Horse.dds WhiteFlag=0 CivType=CIVILIZATION_MONGOL Color=PLAYERCOLOR_BROWN ArtStyle=ARTSTYLE_ASIAN PlayableCiv=1 MinorNationStatus=0 StartingGold=100 StartingX=99, StartingY=51 StateReligion= StartingEra=ERA_ANCIENT RandomStartLocation=false CivicOption=CIVICOPTION_GOVERNMENT, Civic=CIVIC_DESPOTISM CivicOption=CIVICOPTION_LEGAL, Civic=CIVIC_BARBARISM CivicOption=CIVICOPTION_LABOR, Civic=CIVIC_TRIBALISM CivicOption=CIVICOPTION_ECONOMY, Civic=CIVIC_DECENTRALIZATION CivicOption=CIVICOPTION_RELIGION, Civic=CIVIC_PAGANISM Handicap=HANDICAP_NOBLE EndPlayer | C11: =MID(B11, SEARCH("_", B11) + 1, SEARCH("LeaderName", B11) - SEARCH("_", B11) - 3) -> GENGHIS_KHAN | D11: 8 | E11: {=INDEX('plot type'!EC$2:EC$19, MATCH(SUBSTITUTE($C11, "_", " "), UPPER('plot type'!$EE$2:$EE$19), 0))} -> 87 | F11: {=INDEX('plot type'!ED$2:ED$19, MATCH(SUBSTITUTE($C11, "_", " "), UPPER('plot type'!$EE$2:$EE$19), 0))} -> 41 | G11: =MID(B11, SEARCH("startingx", B11), SEARCH(CHAR(10), B11, SEARCH("startingx", B11)) - SEARCH("startingx", B11)) -> StartingX=99, StartingY=51 | I11: =LEFT(A11, SEARCH("=", A11)) & D11 & MID(A11, SEARCH("Tech", A11) - 2, LEN(A11)) -> BeginTeam TeamID=8 Tech=TECH_THE_WHEEL Tech=TECH_HUNTING RevealMap=0 EndTeam | J11: =LEFT(B11, SEARCH("=", B11)) & D11 & SUBSTITUTE(MID(B11, SEARCH("LeaderType", B11) - 2, LEN(B11)), G11, "StartingX=" & E11 & ",StartingY=" & F11) -> BeginPlayer Team=8 LeaderType=LEADER_GENGHIS_KHAN LeaderName=Genghis Khan CivDesc=Mongolian Empire CivShortDesc=TXT_KEY_CIV_MONGOL_SHORT_DESC CivAdjective=TXT_KEY_CIV_MONGOL_ADJECTIVE FlagDecal=Art/Interface/TeamColor/FlagDECAL_Horse.dds WhiteFlag=0 CivType=CIVILIZATION_MONGOL Color=PLAYERCOLOR_BROWN ArtStyle=ARTSTYLE_ASIAN PlayableCiv=1 MinorNationStatus=0 StartingGold=100 StartingX=87,StartingY=41 StateReligion= StartingEra=ERA_ANCIENT RandomStartLocation=false CivicOption=CIVICOPTION_GOVERNMENT, Civic=CIVIC_DESPOTISM CivicOption=CIVICOPTION_LEGAL, Civic=CIVIC_BARBARISM CivicOption=CIVICOPTION_LABOR, Civic=CIVIC_TRIBALISM CivicOption=CIVICOPTION_ECONOMY, Civic=CIVIC_DECENTRALIZATION CivicOption=CIVICOPTION_RELIGION, Civic=CIVIC_PAGANISM Handicap=HANDICAP_NOBLE EndPlayer
A12: BeginTeam TeamID=0 Tech=TECH_THE_WHEEL Tech=TECH_AGRICULTURE EspionageEverAmount=4 RevealMap=0 EndTeam | B12: BeginPlayer Team=0 LeaderType=LEADER_HATSHEPSUT LeaderName=Hatshepsut CivDesc=Egyptian Empire CivShortDesc=TXT_KEY_CIV_EGYPT_SHORT_DESC CivAdjective=TXT_KEY_CIV_EGYPT_ADJECTIVE FlagDecal=Art/Interface/TeamColor/FlagDECAL_EyeOfRa.dds WhiteFlag=0 CivType=CIVILIZATION_EGYPT Color=PLAYERCOLOR_YELLOW ArtStyle=ARTSTYLE_MIDDLE_EAST PlayableCiv=1 MinorNationStatus=0 StartingGold=100 StartingX=69, StartingY=23 StateReligion= StartingEra=ERA_ANCIENT RandomStartLocation=false CivicOption=CIVICOPTION_GOVERNMENT, Civic=CIVIC_DESPOTISM CivicOption=CIVICOPTION_LEGAL, Civic=CIVIC_BARBARISM CivicOption=CIVICOPTION_LABOR, Civic=CIVIC_TRIBALISM CivicOption=CIVICOPTION_ECONOMY, Civic=CIVIC_DECENTRALIZATION CivicOption=CIVICOPTION_RELIGION, Civic=CIVIC_PAGANISM Handicap=HANDICAP_NOBLE EndPlayer | C12: =MID(B12, SEARCH("_", B12) + 1, SEARCH("LeaderName", B12) - SEARCH("_", B12) - 3) -> HATSHEPSUT | D12: 9 | E12: {=INDEX('plot type'!EC$2:EC$19, MATCH(SUBSTITUTE($C12, "_", " "), UPPER('plot type'!$EE$2:$EE$19), 0))} -> 50 | F12: {=INDEX('plot type'!ED$2:ED$19, MATCH(SUBSTITUTE($C12, "_", " "), UPPER('plot type'!$EE$2:$EE$19), 0))} -> 7 | G12: =MID(B12, SEARCH("startingx", B12), SEARCH(CHAR(10), B12, SEARCH("startingx", B12)) - SEARCH("startingx", B12)) -> StartingX=69, StartingY=23 | I12: =LEFT(A12, SEARCH("=", A12)) & D12 & MID(A12, SEARCH("Tech", A12) - 2, LEN(A12)) -> BeginTeam TeamID=9 Tech=TECH_THE_WHEEL Tech=TECH_AGRICULTURE EspionageEverAmount=4 RevealMap=0 EndTeam | J12: =LEFT(B12, SEARCH("=", B12)) & D12 & SUBSTITUTE(MID(B12, SEARCH("LeaderType", B12) - 2, LEN(B12)), G12, "StartingX=" & E12 & ",StartingY=" & F12) -> BeginPlayer Team=9 LeaderType=LEADER_HATSHEPSUT LeaderName=Hatshepsut CivDesc=Egyptian Empire CivShortDesc=TXT_KEY_CIV_EGYPT_SHORT_DESC CivAdjective=TXT_KEY_CIV_EGYPT_ADJECTIVE FlagDecal=Art/Interface/TeamColor/FlagDECAL_EyeOfRa.dds WhiteFlag=0 CivType=CIVILIZATION_EGYPT Color=PLAYERCOLOR_YELLOW ArtStyle=ARTSTYLE_MIDDLE_EAST PlayableCiv=1 MinorNationStatus=0 StartingGold=100 StartingX=50,StartingY=7 StateReligion= StartingEra=ERA_ANCIENT RandomStartLocation=false CivicOption=CIVICOPTION_GOVERNMENT, Civic=CIVIC_DESPOTISM CivicOption=CIVICOPTION_LEGAL, Civic=CIVIC_BARBARISM CivicOption=CIVICOPTION_LABOR, Civic=CIVIC_TRIBALISM CivicOption=CIVICOPTION_ECONOMY, Civic=CIVIC_DECENTRALIZATION CivicOption=CIVICOPTION_RELIGION, Civic=CIVIC_PAGANISM Handicap=HANDICAP_NOBLE EndPlayer
A13: BeginTeam TeamID=15 Tech=TECH_MYSTICISM Tech=TECH_AGRICULTURE RevealMap=0 EndTeam | B13: BeginPlayer Team=15 LeaderType=LEADER_HUAYNA_CAPAC LeaderName=Huayna Capac CivDesc=Incan Empire CivShortDesc=TXT_KEY_CIV_INCA_SHORT_DESC CivAdjective=TXT_KEY_CIV_INCA_ADJECTIVE FlagDecal=Art/Interface/TeamColor/FlagDECAL_Sun.dds WhiteFlag=0 CivType=CIVILIZATION_INCA Color=PLAYERCOLOR_DARK_YELLOW ArtStyle=ARTSTYLE_SOUTH_AMERICA PlayableCiv=1 MinorNationStatus=0 StartingGold=100 StartingX=87, StartingY=8 StateReligion= StartingEra=ERA_ANCIENT RandomStartLocation=false CivicOption=CIVICOPTION_GOVERNMENT, Civic=CIVIC_DESPOTISM CivicOption=CIVICOPTION_LEGAL, Civic=CIVIC_BARBARISM CivicOption=CIVICOPTION_LABOR, Civic=CIVIC_TRIBALISM CivicOption=CIVICOPTION_ECONOMY, Civic=CIVIC_DECENTRALIZATION CivicOption=CIVICOPTION_RELIGION, Civic=CIVIC_PAGANISM Handicap=HANDICAP_NOBLE EndPlayer | C13: =MID(B13, SEARCH("_", B13) + 1, SEARCH("LeaderName", B13) - SEARCH("_", B13) - 3) -> HUAYNA_CAPAC | D13: 10 | E13: {=INDEX('plot type'!EC$2:EC$19, MATCH(SUBSTITUTE($C13, "_", " "), UPPER('plot type'!$EE$2:$EE$19), 0))} -> 107 | F13: {=INDEX('plot type'!ED$2:ED$19, MATCH(SUBSTITUTE($C13, "_", " "), UPPER('plot type'!$EE$2:$EE$19), 0))} -> 8 | G13: =MID(B13, SEARCH("startingx", B13), SEARCH(CHAR(10), B13, SEARCH("startingx", B13)) - SEARCH("startingx", B13)) -> StartingX=87, StartingY=8 | I13: =LEFT(A13, SEARCH("=", A13)) & D13 & MID(A13, SEARCH("Tech", A13) - 2, LEN(A13)) -> BeginTeam TeamID=10 Tech=TECH_MYSTICISM Tech=TECH_AGRICULTURE RevealMap=0 EndTeam | J13: =LEFT(B13, SEARCH("=", B13)) & D13 & SUBSTITUTE(MID(B13, SEARCH("LeaderType", B13) - 2, LEN(B13)), G13, "StartingX=" & E13 & ",StartingY=" & F13) -> BeginPlayer Team=10 LeaderType=LEADER_HUAYNA_CAPAC LeaderName=Huayna Capac CivDesc=Incan Empire CivShortDesc=TXT_KEY_CIV_INCA_SHORT_DESC CivAdjective=TXT_KEY_CIV_INCA_ADJECTIVE FlagDecal=Art/Interface/TeamColor/FlagDECAL_Sun.dds WhiteFlag=0 CivType=CIVILIZATION_INCA Color=PLAYERCOLOR_DARK_YELLOW ArtStyle=ARTSTYLE_SOUTH_AMERICA PlayableCiv=1 MinorNationStatus=0 StartingGold=100 StartingX=107,StartingY=8 StateReligion= StartingEra=ERA_ANCIENT RandomStartLocation=false CivicOption=CIVICOPTION_GOVERNMENT, Civic=CIVIC_DESPOTISM CivicOption=CIVICOPTION_LEGAL, Civic=CIVIC_BARBARISM CivicOption=CIVICOPTION_LABOR, Civic=CIVIC_TRIBALISM CivicOption=CIVICOPTION_ECONOMY, Civic=CIVIC_DECENTRALIZATION CivicOption=CIVICOPTION_RELIGION, Civic=CIVIC_PAGANISM Handicap=HANDICAP_NOBLE EndPlayer
A14: BeginTeam TeamID=11 Tech=TECH_MYSTICISM Tech=TECH_FISHING RevealMap=0 EndTeam | B14: BeginPlayer Team=11 LeaderType=LEADER_ISABELLA LeaderName=Isabella CivDesc=Spanish Empire CivShortDesc=TXT_KEY_CIV_SPAIN_SHORT_DESC CivAdjective=TXT_KEY_CIV_SPAIN_ADJECTIVE FlagDecal=Art/Interface/TeamColor/FlagDECAL_Castle.dds WhiteFlag=0 CivType=CIVILIZATION_SPAIN Color=PLAYERCOLOR_PINK ArtStyle=ARTSTYLE_EUROPEAN PlayableCiv=1 MinorNationStatus=0 StartingGold=100 StartingX=65, StartingY=46 StateReligion= StartingEra=ERA_ANCIENT RandomStartLocation=false CivicOption=CIVICOPTION_GOVERNMENT, Civic=CIVIC_DESPOTISM CivicOption=CIVICOPTION_LEGAL, Civic=CIVIC_BARBARISM CivicOption=CIVICOPTION_LABOR, Civic=CIVIC_TRIBALISM CivicOption=CIVICOPTION_ECONOMY, Civic=CIVIC_DECENTRALIZATION CivicOption=CIVICOPTION_RELIGION, Civic=CIVIC_PAGANISM Handicap=HANDICAP_NOBLE EndPlayer | C14: =MID(B14, SEARCH("_", B14) + 1, SEARCH("LeaderName", B14) - SEARCH("_", B14) - 3) -> ISABELLA | D14: 11 | E14: {=INDEX('plot type'!EC$2:EC$19, MATCH(SUBSTITUTE($C14, "_", " "), UPPER('plot type'!$EE$2:$EE$19), 0))} -> 87 | F14: {=INDEX('plot type'!ED$2:ED$19, MATCH(SUBSTITUTE($C14, "_", " "), UPPER('plot type'!$EE$2:$EE$19), 0))} -> 28 | G14: =MID(B14, SEARCH("startingx", B14), SEARCH(CHAR(10), B14, SEARCH("startingx", B14)) - SEARCH("startingx", B14)) -> StartingX=65, StartingY=46 | I14: =LEFT(A14, SEARCH("=", A14)) & D14 & MID(A14, SEARCH("Tech", A14) - 2, LEN(A14)) -> BeginTeam TeamID=11 Tech=TECH_MYSTICISM Tech=TECH_FISHING RevealMap=0 EndTeam | J14: =LEFT(B14, SEARCH("=", B14)) & D14 & SUBSTITUTE(MID(B14, SEARCH("LeaderType", B14) - 2, LEN(B14)), G14, "StartingX=" & E14 & ",StartingY=" & F14) -> BeginPlayer Team=11 LeaderType=LEADER_ISABELLA LeaderName=Isabella CivDesc=Spanish Empire CivShortDesc=TXT_KEY_CIV_SPAIN_SHORT_DESC CivAdjective=TXT_KEY_CIV_SPAIN_ADJECTIVE FlagDecal=Art/Interface/TeamColor/FlagDECAL_Castle.dds WhiteFlag=0 CivType=CIVILIZATION_SPAIN Color=PLAYERCOLOR_PINK ArtStyle=ARTSTYLE_EUROPEAN PlayableCiv=1 MinorNationStatus=0 StartingGold=100 StartingX=87,StartingY=28 StateReligion= StartingEra=ERA_ANCIENT RandomStartLocation=false CivicOption=CIVICOPTION_GOVERNMENT, Civic=CIVIC_DESPOTISM CivicOption=CIVICOPTION_LEGAL, Civic=CIVIC_BARBARISM CivicOption=CIVICOPTION_LABOR, Civic=CIVIC_TRIBALISM CivicOption=CIVICOPTION_ECONOMY, Civic=CIVIC_DECENTRALIZATION CivicOption=CIVICOPTION_RELIGION, Civic=CIVIC_PAGANISM Handicap=HANDICAP_NOBLE EndPlayer
... A20: BeginTeam TeamID=6 Tech=TECH_FISHING Tech=TECH_THE_WHEEL RevealMap=0 EndTeam | B20: BeginPlayer Team=6 LeaderType=LEADER_TOKUGAWA LeaderName=Tokugawa CivDesc=Japanese Empire CivShortDesc=TXT_KEY_CIV_JAPAN_SHORT_DESC CivAdjective=TXT_KEY_CIV_JAPAN_ADJECTIVE FlagDecal=Art/Interface/TeamColor/FlagDECAL_Dot.dds WhiteFlag=0 CivType=CIVILIZATION_JAPAN Color=PLAYERCOLOR_RED ArtStyle=ARTSTYLE_ASIAN PlayableCiv=1 MinorNationStatus=0 StartingGold=100 StartingX=105, StartingY=60 StateReligion= StartingEra=ERA_ANCIENT RandomStartLocation=false CivicOption=CIVICOPTION_GOVERNMENT, Civic=CIVIC_DESPOTISM CivicOption=CIVICOPTION_LEGAL, Civic=CIVIC_BARBARISM CivicOption=CIVICOPTION_LABOR, Civic=CIVIC_TRIBALISM CivicOption=CIVICOPTION_ECONOMY, Civic=CIVIC_DECENTRALIZATION CivicOption=CIVICOPTION_RELIGION, Civic=CIVIC_PAGANISM Handicap=HANDICAP_NOBLE EndPlayer | C20: =MID(B20, SEARCH("_", B20) + 1, SEARCH("LeaderName", B20) - SEARCH("_", B20) - 3) -> TOKUGAWA | D20: 17 | E20: {=INDEX('plot type'!EC$2:EC$19, MATCH(SUBSTITUTE($C20, "_", " "), UPPER('plot type'!$EE$2:$EE$19), 0))} -> 107 | F20: {=INDEX('plot type'!ED$2:ED$19, MATCH(SUBSTITUTE($C20, "_", " "), UPPER('plot type'!$EE$2:$EE$19), 0))} -> 41 | G20: =MID(B20, SEARCH("startingx", B20), SEARCH(CHAR(10), B20, SEARCH("startingx", B20)) - SEARCH("startingx", B20)) -> StartingX=105, StartingY=60 | I20: =LEFT(A20, SEARCH("=", A20)) & D20 & MID(A20, SEARCH("Tech", A20) - 2, LEN(A20)) -> BeginTeam TeamID=17 Tech=TECH_FISHING Tech=TECH_THE_WHEEL RevealMap=0 EndTeam | J20: =LEFT(B20, SEARCH("=", B20)) & D20 & SUBSTITUTE(MID(B20, SEARCH("LeaderType", B20) - 2, LEN(B20)), G20, "StartingX=" & E20 & ",StartingY=" & F20) -> BeginPlayer Team=17 LeaderType=LEADER_TOKUGAWA LeaderName=Tokugawa CivDesc=Japanese Empire CivShortDesc=TXT_KEY_CIV_JAPAN_SHORT_DESC CivAdjective=TXT_KEY_CIV_JAPAN_ADJECTIVE FlagDecal=Art/Interface/TeamColor/FlagDECAL_Dot.dds WhiteFlag=0 CivType=CIVILIZATION_JAPAN Color=PLAYERCOLOR_RED ArtStyle=ARTSTYLE_ASIAN PlayableCiv=1 MinorNationStatus=0 StartingGold=100 StartingX=107,StartingY=41 StateReligion= StartingEra=ERA_ANCIENT RandomStartLocation=false CivicOption=CIVICOPTION_GOVERNMENT, Civic=CIVIC_DESPOTISM CivicOption=CIVICOPTION_LEGAL, Civic=CIVIC_BARBARISM CivicOption=CIVICOPTION_LABOR, Civic=CIVIC_TRIBALISM CivicOption=CIVICOPTION_ECONOMY, Civic=CIVIC_DECENTRALIZATION CivicOption=CIVICOPTION_RELIGION, Civic=CIVIC_PAGANISM Handicap=HANDICAP_NOBLE EndPlayer
B23: =LEN(A3) -> 103 | C23: =LEN(B3) -> 810
